{"uuid": "44e19493-8a41-41db-9b61-5574e38cdc77", "children": ["eba94cf7-301b-4393-a580-4ad0a27aa03d"], "befores": [{"name": "ui_report", "status": "passed", "start": 1648648164069, "stop": 1648648164069}], "afters": [{"name": "ui_report::0", "status": "broken", "statusDetails": {"message": "FileNotFoundError: [Errno 2] No such file or directory: '/tmp/tests/test_login.py::TestLogin::test_user_authorization_negative_wrong_passw/failed.png'\n", "trace": "  File \"/usr/local/lib/python3.8/dist-packages/allure_commons/_allure.py\", line 200, in __call__\n    return self._fixture_function(*args, **kwargs)\n  File \"/usr/local/lib/python3.8/dist-packages/_pytest/fixtures.py\", line 899, in _teardown_yield_fixture\n    next(it)\n  File \"/home/doychevvs/vk/2022-1-QAPYTHON-VK-V-Doychev/homework2/base.py\", line 25, in ui_report\n    allure.attach.file(screenshot_path, 'failed.png', allure.attachment_type.PNG)\n  File \"/usr/local/lib/python3.8/dist-packages/allure_commons/_allure.py\", line 182, in file\n    plugin_manager.hook.attach_file(source=source, name=name, attachment_type=attachment_type, extension=extension)\n  File \"/usr/local/lib/python3.8/dist-packages/pluggy/_hooks.py\", line 265, in __call__\n    return self._hookexec(self.name, self.get_hookimpls(), kwargs, firstresult)\n  File \"/usr/local/lib/python3.8/dist-packages/pluggy/_manager.py\", line 80, in _hookexec\n    return self._inner_hookexec(hook_name, methods, kwargs, firstresult)\n  File \"/usr/local/lib/python3.8/dist-packages/pluggy/_callers.py\", line 60, in _multicall\n    return outcome.get_result()\n  File \"/usr/local/lib/python3.8/dist-packages/pluggy/_result.py\", line 60, in get_result\n    raise ex[1].with_traceback(ex[2])\n  File \"/usr/local/lib/python3.8/dist-packages/pluggy/_callers.py\", line 39, in _multicall\n    res = hook_impl.function(*args)\n  File \"/usr/local/lib/python3.8/dist-packages/allure_pytest/listener.py\", line 224, in attach_file\n    self.allure_logger.attach_file(uuid4(), source, name=name, attachment_type=attachment_type, extension=extension)\n  File \"/usr/local/lib/python3.8/dist-packages/allure_commons/reporter.py\", line 113, in attach_file\n    plugin_manager.hook.report_attached_file(source=source, file_name=file_name)\n  File \"/usr/local/lib/python3.8/dist-packages/pluggy/_hooks.py\", line 265, in __call__\n    return self._hookexec(self.name, self.get_hookimpls(), kwargs, firstresult)\n  File \"/usr/local/lib/python3.8/dist-packages/pluggy/_manager.py\", line 80, in _hookexec\n    return self._inner_hookexec(hook_name, methods, kwargs, firstresult)\n  File \"/usr/local/lib/python3.8/dist-packages/pluggy/_callers.py\", line 60, in _multicall\n    return outcome.get_result()\n  File \"/usr/local/lib/python3.8/dist-packages/pluggy/_result.py\", line 60, in get_result\n    raise ex[1].with_traceback(ex[2])\n  File \"/usr/local/lib/python3.8/dist-packages/pluggy/_callers.py\", line 39, in _multicall\n    res = hook_impl.function(*args)\n  File \"/usr/local/lib/python3.8/dist-packages/allure_commons/logger.py\", line 53, in report_attached_file\n    shutil.copy2(source, destination)\n  File \"/usr/lib/python3.8/shutil.py\", line 435, in copy2\n    copyfile(src, dst, follow_symlinks=follow_symlinks)\n  File \"/usr/lib/python3.8/shutil.py\", line 264, in copyfile\n    with open(src, 'rb') as fsrc, open(dst, 'wb') as fdst:\n"}, "attachments": [{"name": "failed.png", "source": "19748756-af1b-4b9c-a69a-8ea971700db0-attachment.png", "type": "image/png"}], "start": 1648648170460, "stop": 1648648170465}], "start": 1648648164069, "stop": 1648648170466}